<?xml version="1.0"?>
<robot xmlns:xacro="http://www.ros.org/wiki/xacro">

  <xacro:include filename="$(find husky_ur_description)/urdf/husky_ur5_e_description.urdf.xacro" />

  <xacro:macro name="deploy_husky_ur5e" params="prefix attach_to_world loc_x loc_y orientation">

    <!-- Virtual Link Starts -->
    <link name="${prefix}virtual_base_x">
      <!-- <visual >
      <origin xyz="0.0 0.0 0.0" rpy="0 0 0" />
      <geometry>
        <box size="0.5 0.1 0.1"/>
      </geometry>
      <material name="${prefix}red"> 
        <color rgba="1.0 0.0 0.0 1.0"/>
      </material>
    </visual> -->
    </link>

    <link name="${prefix}virtual_base_y">
      <!-- <visual >
      <origin xyz="0.0 0.0 0.0" rpy="0 0 0" />
      <geometry>
        <box size="0.1 0.5 0.1"/>
      </geometry>
      <material name="${prefix}blue">
        <color rgba="0.0 1.0 0.0 1.0"/>
      </material>
    </visual> -->
    </link>

    <link name="${prefix}virtual_base_theta">
      <!-- <visual >
      <origin xyz="0.0 0.0 0.0" rpy="0 0 0" />
      <geometry>
        <box size="0.1 0.5 0.1"/>
      </geometry>
      <material name="${prefix}blue">
        <color rgba="0.0 1.0 0.0 1.0"/>
      </material>
    </visual> -->
    </link>
    <!-- Virtual Link Ends -->

    <joint name="${prefix}base_link_base_theta" type="revolute">
      <parent link="${prefix}virtual_base_theta" />
      <origin xyz="0.0 0.0 0.0" rpy="0 0 0" />
      <child link="base_link" />
      <axis xyz="0 0 1"/>
      <limit effort="20" velocity="5.0" lower="-3.14" upper="3.14"/>
    </joint>

    <joint name="${prefix}base_theta_base_y" type="prismatic">
      <parent link="${prefix}virtual_base_y" />
      <origin xyz="0.0 0.0 0.0" rpy="0 0 0" />
      <child link="${prefix}virtual_base_theta" />
      <axis xyz="0 1 0"/>
      <limit effort="20" velocity="5.0" lower="-10" upper="10"/>
    </joint>

    <joint name="${prefix}base_y_base_x" type="prismatic">
      <parent link="${prefix}virtual_base_x" />
      <origin xyz="0.0 0.0 0.0" rpy="0 0 0" />
      <child link="${prefix}virtual_base_y" />
      <axis xyz="1 0 0"/>
      <limit effort="20" velocity="5.0" lower="-10" upper="10"/>
    </joint>

    <xacro:if value="${attach_to_world}">
      <joint name="${prefix}world" type="fixed">
        <child link="${prefix}virtual_base_x" />
        <parent link="world" />
        <origin xyz="${loc_x} ${loc_y} 0.13" rpy="0 0 ${orientation}" />
      </joint>
    </xacro:if>

  </xacro:macro>
</robot>